Workbook
Name UPDATE: 'Raw Financial Data'!$E$1

Sheet Cover Sheet
A1: Project Overview
A3: Field | B3: Details
A4: Project | B4: Adani Enterprises Financial Analysis
A5: Domain | B5: Corporate Finance
A6: Tools Used | B6: Excel, Financial Modeling
A7: Analysis Includes | B7: Beta, WACC, Cost of Debt, PE Valuation
A8: Company | B8: Adani Enterprises Ltd

Sheet Nifty 50 
A1: Date | B1: Price | C1: Open | D1: High | E1: Low | F1: Vol. | G1: Change %
A2: 46111 | B2: 22331.4 | C2: 22549.65 | D2: 22714.1 | E2: 22283.85 | F2: 698.60M | G2: -0.0214
A3: 46108 | B3: 22819.6 | C3: 23173.55 | D3: 23186.1 | E3: 22804.55 | F3: 612.56M | G3: -0.0209
A4: 46106 | B4: 23306.45 | C4: 23064.4 | D4: 23465.35 | E4: 23063.2 | F4: 505.42M | G4: 0.0172
A5: 46105 | B5: 22912.4 | C5: 22878.45 | D5: 23057.3 | E5: 22624.2 | F5: 538.10M | G5: 0.0178
A6: 46104 | B6: 22512.65 | C6: 22824.35 | D6: 22851.7 | E6: 22471.25 | F6: 550.28M | G6: -0.026
A7: 46101 | B7: 23114.5 | C7: 23110.15 | D7: 23345.15 | E7: 23067.6 | F7: 663.29M | G7: 0.0049
A8: 46100 | B8: 23002.15 | C8: 23197.75 | D8: 23378.7 | E8: 22930.35 | F8: 550.15M | G8: -0.0326
A9: 46099 | B9: 23777.8 | C9: 23632.9 | D9: 23862.25 | E9: 23618.45 | F9: 382.88M | G9: 0.0083
A10: 46098 | B10: 23581.15 | C10: 23493.2 | D10: 23656.8 | E10: 23346.6 | F10: 458.79M | G10: 0.0074
A11: 46097 | B11: 23408.8 | C11: 23116.1 | D11: 23502 | E11: 22955.25 | F11: 540.29M | G11: 0.0111
A12: 46094 | B12: 23151.1 | C12: 23462.5 | D12: 23492.4 | E12: 23112 | F12: 519.78M | G12: -0.0206
A13: 46093 | B13: 23639.15 | C13: 23674.85 | D13: 23833.15 | E13: 23556.3 | F13: 501.00M | G13: -0.0095
... A524: 45342 | B524: 22196.95 | C524: 22099.2 | D524: 22215.6 | E524: 22045.85 | F524: 295.71M | G524: 0.0034
A525: 45341 | B525: 22122.25 | C525: 22103.45 | D525: 22186.65 | E525: 22021.05 | G525: 0.0037
A526: 45338 | B526: 22040.7 | C526: 22020.3 | D526: 22068.65 | E526: 21968.95 | F526: 343.89M | G526: 0.0059
A527: 45337 | B527: 21910.75 | C527: 21906.55 | D527: 21953.85 | E527: 21794.8 | F527: 345.39M | G527: 0.0032
A528: 45336 | B528: 21840.05 | C528: 21578.15 | D528: 21870.85 | E528: 21530.2 | F528: 359.12M | G528: 0.0045
A529: 45335 | B529: 21743.25 | C529: 21664.3 | D529: 21766.8 | E529: 21543.35 | F529: 365.79M | G529: 0.0059
A530: 45334 | B530: 21616.05 | C530: 21800.8 | D530: 21831.7 | E530: 21574.75 | F530: 287.44M | G530: -0.0076
A531: 45331 | B531: 21782.5 | C531: 21727 | D531: 21804.45 | E531: 21629.9 | F531: 349.22M | G531: 0.003
A532: 45330 | B532: 21717.95 | C532: 22009.65 | D532: 22011.05 | E532: 21665.3 | F532: 491.07M | G532: -0.0097
A533: 45329 | B533: 21930.5 | C533: 22045.05 | D533: 22053.3 | E533: 21860.15 | F533: 346.26M | G533: 0.0001
A534: 45328 | B534: 21929.4 | C534: 21825.2 | D534: 21951.4 | E534: 21737.55 | F534: 370.97M | G534: 0.0072
A535: 45327 | B535: 21771.7 | C535: 21921.05 | D535: 21964.3 | E535: 21726.95 | F535: 440.85M | G535: -0.0038
A536: 45324 | B536: 21853.8 | C536: 21812.75 | D536: 22126.8 | E536: 21805.55 | F536: 442.79M | G536: 0.0072
A537: 45323 | B537: 21697.45 | C537: 21780.65 | D537: 21832.95 | E537: 21658.75 | F537: 332.54M | G537: -0.0013
... A543: 45314 | B543: 21238.8 | C543: 21716.7 | D543: 21750.25 | E543: 21192.6 | F543: 449.72M | G543: -0.0154
A544: 45311 | B544: 21571.8 | C544: 21706.15 | D544: 21720.3 | E544: 21541.8 | G544: -0.0023
A545: 45310 | B545: 21622.4 | C545: 21615.2 | D545: 21670.6 | E545: 21575 | F545: 343.06M | G545: 0.0075
A546: 45309 | B546: 21462.25 | C546: 21414.2 | D546: 21539.4 | E546: 21285.55 | F546: 387.34M | G546: -0.0051
A547: 45308 | B547: 21571.95 | C547: 21647.25 | D547: 21851.5 | E547: 21550.45 | F547: 456.00M | G547: -0.0209
A548: 45307 | B548: 22032.3 | C548: 22080.5 | D548: 22124.15 | E548: 21969.8 | F548: 292.43M | G548: -0.0029
A549: 45306 | B549: 22097.45 | C549: 22053.15 | D549: 22115.55 | E549: 21963.55 | F549: 345.54M | G549: 0.0093
A550: 45303 | B550: 21894.55 | C550: 21773.55 | D550: 21928.25 | E550: 21715.15 | F550: 294.68M | G550: 0.0114
A551: 45302 | B551: 21647.2 | C551: 21688 | D551: 21726.5 | E551: 21593.75 | F551: 212.45M | G551: 0.0013
A552: 45301 | B552: 21618.7 | C552: 21529.3 | D552: 21641.85 | E552: 21448.65 | F552: 216.99M | G552: 0.0034
A553: 45300 | B553: 21544.85 | C553: 21653.6 | D553: 21724.45 | E553: 21517.85 | F553: 228.57M | G553: 0.0015
A554: 45299 | B554: 21513 | C554: 21747.6 | D554: 21763.95 | E554: 21492.9 | F554: 231.45M | G554: -0.0091
A555: 45296 | B555: 21710.8 | C555: 21705.75 | D555: 21749.6 | E555: 21629.2 | F555: 309.30M | G555: 0.0024
...

Sheet Beta Analysis
A1: Date | B1: Adani Ent. | C1: Nifty 50 | D1: Returns | H1: Beta | I1: =SLOPE(D2:D1240,E2:E1240) -> 1.756611
A2: 46111 | B2: 1758.8 | C2: =VLOOKUP(A:A,'Nifty 50 '!$A:$B,2,0) -> 22331.4 | D2: AdaniEnt. | E2: Nifty 50 | H2: Rf | I2: 0.0695
A3: 46108 | B3: 1823 | C3: =VLOOKUP(A:A,'Nifty 50 '!$A:$B,2,0) -> 22819.6 | D3: =LN(B2/B3) -> -0.035851737 | E3: =LN(C2/C3) -> -0.021626056 | H3: Rm | I3: =SUM(E2:E1240)/5 -> 0.081365245
A4: 46106 | B4: 1886.6 | C4: =VLOOKUP(A:A,'Nifty 50 '!$A:$B,2,0) -> 23306.45 | D4: =LN(B3/B4) -> -0.034292772 | E4: =LN(C3/C4) -> -0.021110331 | H4: Leverage Beta | I4: Unleveraged Beta*(1+(1-t)*Debt/Equity)
A5: 46105 | B5: 1817.9 | C5: =VLOOKUP(A:A,'Nifty 50 '!$A:$B,2,0) -> 22912.4 | D5: =LN(B4/B5) -> 0.037094278 | E5: =LN(C4/C5) -> 0.017051898 | H5: Leverage Beta | I5: =I1*(1+(1-'Cost Of Debt Analysis'!G7)*'Capital Structure'!C5/'Capital Structure'!C4) -> 2.1614477
A6: 46104 | B6: 1833 | C6: =VLOOKUP(A:A,'Nifty 50 '!$A:$B,2,0) -> 22512.65 | D6: =LN(B5/B6) -> -0.0082719801 | E6: =LN(C5/C6) -> 0.017600875
A7: 46101 | B7: 1927.1 | C7: =VLOOKUP(A:A,'Nifty 50 '!$A:$B,2,0) -> 23114.5 | D7: =LN(B6/B7) -> -0.050062313 | E7: =LN(C6/C7) -> -0.026382753 | H7: Ke | I7: Rf + Beta*(Rm-Rf)
A8: 46100 | B8: 1936.8 | C8: =VLOOKUP(A:A,'Nifty 50 '!$A:$B,2,0) -> 23002.15 | D8: =LN(B7/B8) -> -0.0050208444 | E8: =LN(C7/C8) -> 0.0048724364 | H8: Ke | I8: =I2+I5*(I3-I2) -> 0.095146107
A9: 46099 | B9: 2007.2 | C9: =VLOOKUP(A:A,'Nifty 50 '!$A:$B,2,0) -> 23777.8 | D9: =LN(B8/B9) -> -0.035703589 | E9: =LN(C8/C9) -> -0.033164682
A10: 46098 | B10: 1975.4 | C10: =VLOOKUP(A:A,'Nifty 50 '!$A:$B,2,0) -> 23581.15 | D10: =LN(B9/B10) -> 0.015969807 | E10: =LN(C9/C10) -> 0.0083047082
A11: 46097 | B11: 1978 | C11: =VLOOKUP(A:A,'Nifty 50 '!$A:$B,2,0) -> 23408.8 | D11: =LN(B10/B11) -> -0.0013153237 | E11: =LN(C10/C11) -> 0.007335644
A12: 46094 | B12: 1961.1 | C12: =VLOOKUP(A:A,'Nifty 50 '!$A:$B,2,0) -> 23151.1 | D12: =LN(B11/B12) -> 0.0085806929 | E12: =LN(C11/C12) -> 0.011069724
A13: 46093 | B13: 2002 | C13: =VLOOKUP(A:A,'Nifty 50 '!$A:$B,2,0) -> 23639.15 | D13: =LN(B12/B13) -> -0.020641141 | E13: =LN(C12/C13) -> -0.02086194
A14: 46092 | B14: 1974.7 | C14: =VLOOKUP(A:A,'Nifty 50 '!$A:$B,2,0) -> 23866.85 | D14: =LN(B13/B14) -> 0.013730193 | E14: =LN(C13/C14) -> -0.0095862309
A15: 46091 | B15: 1996.5 | C15: =VLOOKUP(A:A,'Nifty 50 '!$A:$B,2,0) -> 24261.6 | D15: =LN(B14/B15) -> -0.010979159 | E15: =LN(C14/C15) -> -0.016404387
A16: 46090 | B16: 1999.2 | C16: =VLOOKUP(A:A,'Nifty 50 '!$A:$B,2,0) -> 24028.05 | D16: =LN(B15/B16) -> -0.001351453 | E16: =LN(C15/C16) -> 0.0096729556
A17: 46087 | B17: 2039.9 | C17: =VLOOKUP(A:A,'Nifty 50 '!$A:$B,2,0) -> 24450.45 | D17: =LN(B16/B17) -> -0.020153687 | E17: =LN(C16/C17) -> -0.017426723
A18: 46086 | B18: 2089.2 | C18: =VLOOKUP(A:A,'Nifty 50 '!$A:$B,2,0) -> 24765.9 | D18: =LN(B17/B18) -> -0.023880431 | E18: =LN(C17/C18) -> -0.012819086
A19: 46085 | B19: 2076.5 | C19: =VLOOKUP(A:A,'Nifty 50 '!$A:$B,2,0) -> 24480.5 | D19: =LN(B18/B19) -> 0.0060974335 | E19: =LN(C18/C19) -> 0.011590825
A20: 46083 | B20: 2124.6 | C20: =VLOOKUP(A:A,'Nifty 50 '!$A:$B,2,0) -> 24865.7 | D20: =LN(B19/B20) -> -0.022899765 | E20: =LN(C19/C20) -> -0.015612462
... A1240: 44287 | B1240: 1107.2 | C1240: =VLOOKUP(A:A,'Nifty 50 '!$A:$B,2,0) -> 14867.35 | D1240: =LN(B1239/B1240) -> 0.027657689 | E1240: =LN(C1239/C1240) -> -0.015560309

Sheet Capital Structure
A1: Capital Structure Of Adani Enterprices Ltd.
B3: BV | C3: MV | D3: Cost | E3: Weights BV | F3: Weights MV | G3: WACC BV | H3: WACC MV
A4: Equity | B4: ='Balance Sheet'!F4+'Balance Sheet'!F5 -> 50313.97 | C4: ='Raw Financial Data'!K90*'Raw Financial Data'!K70/10000000 -> 259128.58 | D4: ='Beta Analysis'!I8 -> 0.095146107 | E4: =B4/B6 -> 0.35399183 | F4: =C4/C6 -> 0.73836797 | G4: =D4*E4 -> 0.033680944 | H4: =D4*F4 -> 0.070252838
A5: Debt | B5: ='Balance Sheet'!F6 -> 91819.17 | C5: =B5 -> 91819.17 | D5: ='Cost Of Debt Analysis'!G9 -> 0.018333816 | E5: =B5/B6 -> 0.64600817 | F5: =C5/C6 -> 0.26163203 | G5: =D5*E5 -> 0.011843795 | H5: =D5*F5 -> 0.0047967134
B6: =SUM(B4:B5) -> 142133.14 | C6: =SUM(C4:C5) -> 350947.75 | E6: =SUM(E4:E5) -> 1 | F6: =SUM(F4:F5) -> 1 | G6: =SUM(G4:G5) -> 0.045524739 | H6: =SUM(H4:H5) -> 0.075049552

Sheet PE Valuation Model
A1: PE Valuation Of Adani Enterprices Ltd.
A2: EPS | B2: 118.12
A3: P/E Ratio | B3: 20.8
A4: Price of Share | B4: =B2*B3 -> 2456.896
A5: Current Market Price | B5: 2425.9 | C5: Under Valued

Sheet Cost Of Debt Analysis
A1: ='Raw Financial Data'!B1 -> ADANI ENTERPRISES LTD .
A3: Narration | B3: ='Raw Financial Data'!G16 -> 44286 | C3: ='Raw Financial Data'!H16 -> 44651 | D3: ='Raw Financial Data'!I16 -> 45016 | E3: ='Raw Financial Data'!J16 -> 45382 | F3: ='Raw Financial Data'!K16 -> 45747 | G3: Average
A4: Interest | B4: ='Raw Financial Data'!G27 -> 1376.85 | C4: ='Raw Financial Data'!H27 -> 2525.88 | D4: ='Raw Financial Data'!I27 -> 3968.9 | E4: ='Raw Financial Data'!J27 -> 4554.7 | F4: ='Raw Financial Data'!K27 -> 5978.02 | G4: =AVERAGE(Annual[[#This Row],[Column7]:[Column11]]) -> 3680.87
A5: Profit before tax | B5: ='Raw Financial Data'!G28 -> 1085.97 | C5: ='Raw Financial Data'!H28 -> 952.05 | D5: ='Raw Financial Data'!I28 -> 3246.88 | E5: ='Raw Financial Data'!J28 -> 4926.14 | F5: ='Raw Financial Data'!K28 -> 10465.78 | G5: =AVERAGE(Annual[[#This Row],[Column7]:[Column11]]) -> 4135.364
A6: Tax | B6: ='Raw Financial Data'!G29 -> 339.65 | C6: ='Raw Financial Data'!H29 -> 476.68 | D6: ='Raw Financial Data'!I29 -> 1037.94 | E6: ='Raw Financial Data'!J29 -> 1631.51 | F6: ='Raw Financial Data'!K29 -> 2968.52 | G6: =AVERAGE(Annual[[#This Row],[Column7]:[Column11]]) -> 1290.86
A7: Tax Rate | B7: =B6/B5 -> 0.31276186 | C7: =C6/C5 -> 0.50068799 | D7: =D6/D5 -> 0.31967304 | E7: =E6/E5 -> 0.3311944 | F7: =F6/F5 -> 0.28364059 | G7: =AVERAGE(Annual[[#This Row],[Column7]:[Column11]]) -> 0.34959158
A8: Borrowings | B8: ='Raw Financial Data'!G61 -> 51616.72 | C8: ='Raw Financial Data'!H61 -> 101586.36 | D8: ='Raw Financial Data'!I61 -> 141278.48 | E8: ='Raw Financial Data'!J61 -> 160586.24 | F8: ='Raw Financial Data'!K61 -> 197842.88 | G8: =AVERAGE(Annual[[#This Row],[Column7]:[Column11]]) -> 130582.14
A9: Cost Of Debt | G9: =G4*(1-G7)/G8 -> 0.018333816

Sheet Balance Sheet
A1: ='Cost Of Debt Analysis'!A1 -> ADANI ENTERPRISES LTD . | E1: SCREENER.IN
A3: Narration | B3: ='Raw Financial Data'!G56 -> 44286 | C3: ='Raw Financial Data'!H56 -> 44651 | D3: ='Raw Financial Data'!I56 -> 45016 | E3: ='Raw Financial Data'!J56 -> 45382 | F3: ='Raw Financial Data'!K56 -> 45747
A4: Equity Share Capital | B4: ='Raw Financial Data'!G57 -> 109.98 | C4: ='Raw Financial Data'!H57 -> 109.98 | D4: ='Raw Financial Data'!I57 -> 114 | E4: ='Raw Financial Data'!J57 -> 114 | F4: ='Raw Financial Data'!K57 -> 115.42
A5: Reserves | B5: ='Raw Financial Data'!G58 -> 17048.59 | C5: ='Raw Financial Data'!H58 -> 22146.53 | D5: ='Raw Financial Data'!I58 -> 32937.01 | E5: ='Raw Financial Data'!J58 -> 38962.09 | F5: ='Raw Financial Data'!K58 -> 50198.55
A6: Borrowings | B6: ='Raw Financial Data'!G59 -> 16227.06 | C6: ='Raw Financial Data'!H59 -> 41604.03 | D6: ='Raw Financial Data'!I59 -> 53200.46 | E6: ='Raw Financial Data'!J59 -> 65310.15 | F6: ='Raw Financial Data'!K59 -> 91819.17
A7: Other Liabilities | B7: ='Raw Financial Data'!G60 -> 18231.09 | C7: ='Raw Financial Data'!H60 -> 37725.82 | D7: ='Raw Financial Data'!I60 -> 55027.01 | E7: ='Raw Financial Data'!J60 -> 56200 | F7: ='Raw Financial Data'!K60 -> 55709.74
A8: Total | B8: ='Raw Financial Data'!G61 -> 51616.72 | C8: ='Raw Financial Data'!H61 -> 101586.36 | D8: ='Raw Financial Data'!I61 -> 141278.48 | E8: ='Raw Financial Data'!J61 -> 160586.24 | F8: ='Raw Financial Data'!K61 -> 197842.88
A10: Net Block | B10: ='Raw Financial Data'!G62 -> 10837.61 | C10: ='Raw Financial Data'!H62 -> 30122.77 | D10: ='Raw Financial Data'!I62 -> 56881.13 | E10: ='Raw Financial Data'!J62 -> 65978.3 | F10: ='Raw Financial Data'!K62 -> 77260.14
A11: Capital Work in Progress | B11: ='Raw Financial Data'!G63 -> 8825.46 | C11: ='Raw Financial Data'!H63 -> 23544.42 | D11: ='Raw Financial Data'!I63 -> 24025.21 | E11: ='Raw Financial Data'!J63 -> 35179.5 | F11: ='Raw Financial Data'!K63 -> 51515.81
A12: Investments | B12: ='Raw Financial Data'!G64 -> 5502.94 | C12: ='Raw Financial Data'!H64 -> 4292.21 | D12: ='Raw Financial Data'!I64 -> 6310.17 | E12: ='Raw Financial Data'!J64 -> 8700.69 | F12: ='Raw Financial Data'!K64 -> 9886.61
A13: Other Assets | B13: ='Raw Financial Data'!G65 -> 26450.71 | C13: ='Raw Financial Data'!H65 -> 43626.96 | D13: ='Raw Financial Data'!I65 -> 54061.97 | E13: ='Raw Financial Data'!J65 -> 50727.75 | F13: ='Raw Financial Data'!K65 -> 59180.32
A14: Total | B14: ='Raw Financial Data'!G66 -> 51616.72 | C14: ='Raw Financial Data'!H66 -> 101586.36 | D14: ='Raw Financial Data'!I66 -> 141278.48 | E14: ='Raw Financial Data'!J66 -> 160586.24 | F14: ='Raw Financial Data'!K66 -> 197842.88
A16: Working Capital | B16: =B13-B7 -> 8219.62 | C16: =C13-C7 -> 5901.14 | D16: =D13-D7 -> -965.04 | E16: =E13-E7 -> -5472.25 | F16: =F13-F7 -> 3470.58
A17: Debtors | B17: ='Raw Financial Data'!G67 -> 11982.65 | C17: ='Raw Financial Data'!H67 -> 13712.19 | D17: ='Raw Financial Data'!I67 -> 12552.88 | E17: ='Raw Financial Data'!J67 -> 9792.93 | F17: ='Raw Financial Data'!K67 -> 9616.47
A18: Inventory | B18: ='Raw Financial Data'!G68 -> 1757.04 | C18: ='Raw Financial Data'!H68 -> 6788.28 | D18: ='Raw Financial Data'!I68 -> 6918.05 | E18: ='Raw Financial Data'!J68 -> 9486.86 | F18: ='Raw Financial Data'!K68 -> 10287.39
A20: Return on Equity | B20: =IF(SUM('Balance Sheet'!B4:B5)>0,'Cost Of Debt Analysis'!B15/SUM('Balance Sheet'!B4:B5),"") -> 0 | C20: =IF(SUM('Balance Sheet'!C4:C5)>0,'Cost Of Debt Analysis'!C15/SUM('Balance Sheet'!C4:C5),"") -> 0 | D20: =IF(SUM('Balance Sheet'!D4:D5)>0,'Cost Of Debt Analysis'!D15/SUM('Balance Sheet'!D4:D5),"") -> 0 | E20: =IF(SUM('Balance Sheet'!E4:E5)>0,'Cost Of Debt Analysis'!E15/SUM('Balance Sheet'!E4:E5),"") -> 0 | F20: =IF(SUM('Balance Sheet'!F4:F5)>0,'Cost Of Debt Analysis'!F15/SUM('Balance Sheet'!F4:F5),"") -> 0
A21: Return on Capital Emp | B21: =IF((#REF!+#REF!+#REF!+B4+B5+B6)>0,('Cost Of Debt Analysis'!B5+'Cost Of Debt Analysis'!B4)*2/(#REF!+#REF!+#REF!+B4+B5+B6),"") -> #REF! | C21: =IF((B4+B5+B6+C4+C5+C6)>0,('Cost Of Debt Analysis'!C5+'Cost Of Debt Analysis'!C4)*2/(B4+B5+B6+C4+C5+C6),"") -> 0.07152837 | D21: =IF((C4+C5+C6+D4+D5+D6)>0,('Cost Of Debt Analysis'!D5+'Cost Of Debt Analysis'!D4)*2/(C4+C5+C6+D4+D5+D6),"") -> 0.09613861 | E21: =IF((D4+D5+D6+E4+E5+E6)>0,('Cost Of Debt Analysis'!E5+'Cost Of Debt Analysis'!E4)*2/(D4+D5+D6+E4+E5+E6),"") -> 0.099464476 | F21: =IF((E4+E5+E6+F4+F5+F6)>0,('Cost Of Debt Analysis'!F5+'Cost Of Debt Analysis'!F4)*2/(E4+E5+E6+F4+F5+F6),"") -> 0.13340777

Sheet Raw Financial Data
A1: COMPANY NAME | B1: ADANI ENTERPRISES LTD . | E1: =IF(B2<>B3, "A NEW VERSION OF THE WORKSHEET IS AVAILABLE", "")
A2: LATEST VERSION | B2: 2.1 | E2: PLEASE DO NOT MAKE ANY CHANGES TO THIS SHEET
A3: CURRENT VERSION | B3: 2.1
A5: META
A6: Number of shares | B6: =IF(B9>0, B9/B8, 0) -> 130.17406
A7: Face Value | B7: 1
A8: Current Price | B8: 2425.9
A9: Market Capitalization | B9: 315789.26
A15: PROFIT & LOSS
A16: Report Date | B16: 42460 | C16: 42825 | D16: 43190 | E16: 43555 | F16: 43921 | G16: 44286 | H16: 44651 | I16: 45016 | J16: 45382 | K16: 45747
A17: Sales | B17: 34008.38 | C17: 36532.86 | D17: 35923.92 | E17: 40378.66 | F17: 43402.56 | G17: 39537.13 | H17: 69420.18 | I17: 127539.5 | J17: 96420.98 | K17: 97894.75
A18: Raw Material Cost | B18: 28195.81 | C18: 30945.16 | D18: 30771.08 | E18: 33821.4 | F18: 34350.2 | G18: 29791.08 | H18: 57651.32 | I18: 93814.06 | J18: 51507.72 | K18: 49524.73
A19: Change in Inventory | B19: -226.21 | C19: -36.38 | D19: 772.74 | E19: 499.99 | F19: -310.13 | G19: -456.74 | H19: 3933.82 | I19: 327.16 | J19: 1116.49 | K19: -1844.54
A20: Power and Fuel | B20: 7.5 | C20: 7.42 | D20: 2.91 | E20: 5.74 | F20: 12.22 | G20: 13.4 | H20: 58.98 | I20: 18.42 | J20: 1710.02 | K20: 2037.48
A21: Other Mfr. Exp | B21: 1705.69 | C21: 1910.37 | D21: 2204.89 | E21: 2551.28 | F21: 3115.25 | G21: 4357.88 | H21: 7793.57 | I21: 14377.83 | J21: 20616.96 | K21: 16964.51
A22: Employee Cost | B22: 528.99 | C22: 511.48 | D22: 568.97 | E22: 657.18 | F22: 683.28 | G22: 830.36 | H22: 1182.1 | I22: 1879.07 | J22: 2332.97 | K22: 3121.84
A23: Selling and admin | B23: 1358.01 | C23: 1004.69 | D23: 928.28 | E23: 1230.62 | F23: 1954.57 | G23: 1306.48 | H23: 2412.38 | I23: 8135.29 | J23: 8914.17 | K23: 9245.98
A24: Other Expenses | B24: 302.58 | C24: 215.13 | D24: 182.82 | E24: 643.09 | F24: 682.52 | G24: 275.54 | H24: 542.05 | I24: 824.3 | J24: 1079.03 | K24: 903.64
A25: Other Income | B25: 1043.63 | C25: 749.41 | D25: 363.21 | E25: 504.22 | F25: 872.32 | G25: 494.31 | H25: 1012.11 | I25: 834.23 | J25: 1146.39 | K25: 6403.1
A26: Depreciation | B26: 314.45 | C26: 315.46 | D26: 663.92 | E26: 389.77 | F26: 472.06 | G26: 537.14 | H26: 1247.78 | I26: 2436.14 | J26: 3042.15 | K26: 4211.33
A27: Interest | B27: 1356.99 | C27: 1257.31 | D27: 1250.17 | E27: 1625.07 | F27: 1572.32 | G27: 1376.85 | H27: 2525.88 | I27: 3968.9 | J27: 4554.7 | K27: 5978.02
... A31: Dividend Amount | B31: 43.99 | C31: 43.99 | D31: 43.99 | E31: 43.99 | F31: 109.98 | G31: 109.98 | H31: 109.98 | I31: 136.8 | J31: 148.2 | K31: 150.05
A40: Quarters
A41: Report Date | B41: 45199 | C41: 45291 | D41: 45382 | E41: 45473 | F41: 45565 | G41: 45657 | H41: 45747 | I41: 45838 | J41: 45930 | K41: 46022
A42: Sales | B42: 19546.25 | C42: 25050.23 | D42: 29180.02 | E42: 25472.4 | F42: 22608.07 | G42: 22848.42 | H42: 26965.86 | I42: 21961.2 | J42: 21248.51 | K42: 24819.59
A43: Expenses | B43: 17116.21 | C43: 21824.37 | D43: 25984.58 | E43: 21766.59 | F43: 18842.27 | G43: 19778.01 | H43: 23255.85 | I43: 18650.91 | J43: 17941.95 | K43: 21178.07
A44: Other Income | B44: 460.61 | C44: 491.07 | D44: -175.65 | E44: 590.56 | F44: 582.57 | G44: 648.46 | H44: 4581.51 | I44: 475.42 | J44: 4178.84 | K44: 6287.94
A45: Depreciation | B45: 756.96 | C45: 759.86 | D45: 811.47 | E45: 934.08 | F45: 1035.19 | G45: 1005.65 | H45: 1236.41 | I45: 1283.95 | J45: 1376.55 | K45: 1371.59
A46: Interest | B46: 1342.65 | C46: 596.56 | D46: 1512.62 | E46: 1130.49 | F46: 909.83 | G46: 2141.32 | H46: 1796.38 | I46: 1035.48 | J46: 1711.22 | K46: 1625.94
A47: Profit before tax | B47: 791.04 | C47: 2360.51 | D47: 695.7 | E47: 2231.8 | F47: 2403.35 | G47: 571.9 | H47: 5258.73 | I47: 1466.28 | J47: 4397.63 | K47: 6931.93
A48: Tax | B48: 397.82 | C48: 442.84 | D48: 430.12 | E48: 583.6 | F48: 512.37 | G48: 588.44 | H48: 1284.11 | I48: 571.25 | J48: 1001.07 | K48: 1405.11
A49: Net profit | B49: 227.82 | C49: 1888.45 | D49: 450.58 | E49: 1454.5 | F49: 1741.75 | G49: 57.83 | H49: 3844.91 | I49: 734.41 | J49: 3198.75 | K49: 5627.02
A50: Operating Profit | B50: 2430.04 | C50: 3225.86 | D50: 3195.44 | E50: 3705.81 | F50: 3765.8 | G50: 3070.41 | H50: 3710.01 | I50: 3310.29 | J50: 3306.56 | K50: 3641.52
A55: BALANCE SHEET
A56: Report Date | B56: 42460 | C56: 42825 | D56: 43190 | E56: 43555 | F56: 43921 | G56: 44286 | H56: 44651 | I56: 45016 | J56: 45382 | K56: 45747
A57: Equity Share Capital | B57: 109.98 | C57: 109.98 | D57: 109.98 | E57: 109.98 | F57: 109.98 | G57: 109.98 | H57: 109.98 | I57: 114 | J57: 114 | K57: 115.42
A58: Reserves | B58: 13267.63 | C58: 14025.99 | D58: 14979.19 | E58: 14645.96 | F58: 16836.59 | G58: 17048.59 | H58: 22146.53 | I58: 32937.01 | J58: 38962.09 | K58: 50198.55
A59: Borrowings | B59: 19169.35 | C59: 20845.72 | D59: 17636.69 | E59: 11243.2 | F59: 12419.3 | G59: 16227.06 | H59: 41604.03 | I59: 53200.46 | J59: 65310.15 | K59: 91819.17
A60: Other Liabilities | B60: 9132.42 | C60: 12629.78 | D60: 23679.48 | E60: 16537.04 | F60: 17509.19 | G60: 18231.09 | H60: 37725.82 | I60: 55027.01 | J60: 56200 | K60: 55709.74
A61: Total | B61: 41679.38 | C61: 47611.47 | D61: 56405.34 | E61: 42536.18 | F61: 46875.06 | G61: 51616.72 | H61: 101586.36 | I61: 141278.48 | J61: 160586.24 | K61: 197842.88
...
